Workbook

Sheet HALAMAN AWAL
D1: APLIKASI RPP KURIKULUM MERDEKA (DEEP LEARNING)
A6: Untuk Semua Mata Pelajaran di Jenjang SD, SMP dan SMA
A7: Isi Identitas di Bawah Ini | E7: KEUNGGULAN APLIKASI INI ADALAH :
A8: Nama Sekolah | C8: : | D8: SMA JAYA 1 | E8: 1. | F8: Dibuat khusus untuk mendukung pelaksanaan Kurikulum Merdeka Adaptasi Deep Learning
A9: Nama Kepala Sekolah | C9: : | D9: Hastian Y.A S.Kom
A10: NIP / NUPTK Kepala Sekolah | C10: : | D10: - | E10: 2 | F10: Aplikasi ini sesuai dengan Surat Edaran Mendikbud No. 14 tahun 2019 tentang penyederhanaan rancangan pelaksanaan pembelajaran (RPP)
A11: Nama Guru | C11: : | D11: ROHMAT
A12: NIP / NUPTK Guru | C12: : | D12: -
A13: Mata Pelajaran | C13: : | D13: ILMU PENGETAHUAN ALAM
A14: Kelas / Semester (Fase) | C14: : | D14: II/ Ganjil (Fase E) | E14: 3 | F14: Aplikasi ini sesuai dengan Permendikbud No.37 Tahun 2018 tentang Perubahan Atas Permendikbud Nomor 24 Tahun 2016 tentang Kompetensi Inti dan Kompetensi Dasar
A15: Tahun Pelajaran | C15: : | D15: 2025/2026
A16: Kota dan Tanggal RPP | C16: : | D16: Lampung, 13 Juli 2025
A17: Alokasi Waktu | C17: : | D17: 2x 40 Menit

Sheet Cover
A4: RPP
A6: DEEP LEARNING
A8: ='HALAMAN AWAL'!$D$13 -> ILMU PENGETAHUAN ALAM
K10: Kembali ke Menu Utama
A29: ="KELAS "&'HALAMAN AWAL'!D14 -> KELAS II/ Ganjil (Fase E)
A30: ='HALAMAN AWAL'!D11 -> ROHMAT
A31: ="NIP "&'HALAMAN AWAL'!D12 -> NIP -
A36: ='HALAMAN AWAL'!D8 -> SMA JAYA 1
A37: ="Tahun Pelajaran "&'HALAMAN AWAL'!D15 -> Tahun Pelajaran 2025/2026

Sheet Desain Pembelajaran
F1: DESAIN PEMBELAJARAN
A5: No RPP | B5: Dimensi Profil Lulusan | E5: Tujuan Pembelajaran | H5: Materi Pokok | I5: Praktik Pedagogi (Metode) | J5: Mitra Pembelajaran | K5: Pemanfaatan Digital | L5: Lingkungan Pembelajaran
B6: Dimensi 1 | C6: Dimensi 2 | D6: Dimensi 3 | E6: Tujuan 1 | G6: Tujuan 2
A7: 1 | B7: Penalaran kritis | C7: Kewargaan | D7: Kemandirian | E7: Siswa dapat memahami tentang apa itu makhluk hidup | F7: siswa mampu menjelaskan tentang ciri-cir makhluk hidup | G7: siswa dapat menganalisis ciri-ciri makhluk hidup | H7: Struktur sel dan fungsinya | I7: Pembelajaran berbasis masalah dengan Berdiskusi, Berkelompok dan Presentasi | J7: Lingkungan sekolah dan sekitarnya serta Komunitas masyarakat sekitar ataupun tenaga ahli profesi yang berkaitan dengan topik dibahas | K7: Menampilkan video pembelajaran membantu peserta didik dalam proses pembelajaran melalui youtube ataupun memanfaatkan media publikasi website untuk mengeksplor materi | L7: Pembelajaran dilakukan dengan suasana yang menyenangkan dan sederhana. Guru memanfaatkan lingkungan sekitar sekolah, seperti halaman, taman, atau ruang kelas, sebagai tempat belajar. Siswa diajak mengamati, bercerita, menggambar, dan menulis dengan cara yang sesuai dengan kemampuan mereka. Budaya belajar yang dikembangkan mendorong siswa aktif bertanya, berdiskusi, bekerja sama dalam kelompok kecil, dan berani bercerita di depan teman-teman.
A8: 2 | B8: Penalaran kritis | C8: Kewargaan | D8: Kemandirian | E8: Siswa dapat memahami Pertumbuhan dan perkembangan | F8: siswa mampu menjelaskan tentang ciri-cir makhluk hidup | G8: siswa dapat menganalisis ciri-ciri tumbuh dan berkembang | H8: Pertumbuhan dan Perkembangan | I8: Pembelajaran berbasis masalah dengan Berdiskusi, Berkelompok dan Presentasi | J8: Lingkungan sekolah dan sekitarnya serta Komunitas masyarakat sekitar ataupun tenaga ahli profesi yang berkaitan dengan topik dibahas | K8: Menampilkan video pembelajaran membantu peserta didik dalam proses pembelajaran melalui youtube ataupun memanfaatkan media publikasi website untuk mengeksplor materi | L8: Pembelajaran dilakukan dengan suasana yang menyenangkan dan sederhana. Guru memanfaatkan lingkungan sekitar sekolah, seperti halaman, taman, atau ruang kelas, sebagai tempat belajar. Siswa diajak mengamati, bercerita, menggambar, dan menulis dengan cara yang sesuai dengan kemampuan mereka. Budaya belajar yang dikembangkan mendorong siswa aktif bertanya, berdiskusi, bekerja sama dalam kelompok kecil, dan berani bercerita di depan teman-teman.
A9: 3 | B9: Penalaran kritis | C9: Kewargaan | D9: Kemandirian | E9: Siswa dapat mengetahui dan memahami pengertian sistem pencernaan | F9: siswa mampu menjelaskan tentang ciri-cir makhluk hidup | G9: siswa dapat menganalisis proses terjadinya sistem pencernaan | H9: Sistem Pencernaan | I9: Pembelajaran berbasis masalah dengan Berdiskusi, Berkelompok dan Presentasi | J9: Lingkungan sekolah dan sekitarnya serta Komunitas masyarakat sekitar ataupun tenaga ahli profesi yang berkaitan dengan topik dibahas | K9: Menampilkan video pembelajaran membantu peserta didik dalam proses pembelajaran melalui youtube ataupun memanfaatkan media publikasi website untuk mengeksplor materi | L9: Pembelajaran dilakukan dengan suasana yang menyenangkan dan sederhana. Guru memanfaatkan lingkungan sekitar sekolah, seperti halaman, taman, atau ruang kelas, sebagai tempat belajar. Siswa diajak mengamati, bercerita, menggambar, dan menulis dengan cara yang sesuai dengan kemampuan mereka. Budaya belajar yang dikembangkan mendorong siswa aktif bertanya, berdiskusi, bekerja sama dalam kelompok kecil, dan berani bercerita di depan teman-teman.
A10: 4
A11: 5
A12: 6
A13: 7
A14: 8
A15: 9
A16: 10
A17: 11
A18: 12
A19: 13
A20: 14
A21: 15
... A31: 25

Sheet Langkah Pembelajaran
C1: INPUT LANGKAH PEMBELAJARAN
A5: No RPP | B5: Sintaks Problem Based Learning | G5: Refleksi
B6: Orientasi siswa pada masalah | C6: Mengorganisasi siswa | D6: Membimbing penyelidikan | E6: Mengembangkan dan menyajikan karya | F6: Menganalisis dan mengevaluasi
A7: 1 | B7: Guru mengajak siswa untuk mengamati gambar, benda nyata, atau video, lalu diminta mengemukakan pendapat dan pengalaman mereka yang relevan dengan materi. Guru mencatat ide-ide siswa sebagai dasar untuk melanjutkan ke tahap berikutnya. | C7: Guru membentuk kelompok berisi 4–5 siswa dan membagikan lembar kerja yang memuat tujuan pembelajaran, peran tiap anggota, serta daftar pertanyaan panduan yang harus dijawab melalui pencarian informasi. | D7: Guru mendampingi kelompok dalam menggali informasi dari berbagai sumber (internet, buku, wawancara, data statistik), serta memberikan pertanyaan pengarah seperti: "Apa hubungan antara jumlah kendaraan bermotor dan kadar CO2 di udara?" | E7: Setiap kelompok menyusun presentasi hasil penyelidikan dalam bentuk infografis digital dan menyampaikannya di depan kelas menggunakan media presentasi (misalnya PowerPoint atau Canva). | F7: Siswa dan guru bersama-sama merefleksikan hasil tiap kelompok, membandingkan alternatif solusi, dan melakukan diskusi kelas untuk menentukan solusi paling tepat yang dapat diterapkan di lingkungan sekitar. | G7: Guru membagikan lembar refleksi pribadi dan memandu siswa menuliskan jawaban dari pertanyaan “Apa hal paling menarik yang kamu pelajari hari ini dan apa yang masih membingungkan?
A8: 2 | B8: Guru mengkondisikan peserta didik dengan mengecek kehadiran peserta didik melalui lembar absensi dan mengisi jurnal kelas. Kemudian Guru bersama siswa mengingatkan kesepakatan kelas agar lebih kondusif untuk proses belajar mengajar. | C8: Guru membentuk kelompok berisi 4–5 siswa dan membagikan lembar kerja yang memuat tujuan pembelajaran, peran tiap anggota, serta daftar pertanyaan panduan yang harus dijawab melalui pencarian informasi. | D8: Guru mengajak siswa untuk mengamati gambar, benda nyata, atau video, lalu diminta mengemukakan pendapat dan pengalaman mereka yang relevan dengan materi. Guru mencatat ide-ide siswa sebagai dasar untuk melanjutkan ke tahap berikutnya. | E8: Guru menjelaskan materi pembelajaran secara menarik menggunakan alat peraga, cerita, atau media digital agar mudah dipahami siswa. Siswa kemudian diberikan tugas atau aktivitas seperti percobaan sederhana, permainan edukatif, atau kerja kelompok untuk memperdalam pemahaman. Dalam kelompok, siswa mendiskusikan tugas lalu mempresentasikan hasil kerja mereka di depan kelas. Guru membimbing dan memberi umpan balik selama proses berlangsung. | F8: Guru mengulas kembali materi pembelajaran dan memperkuat konsep-konsep penting yang telah dipelajari. Penjelasan tambahan diberikan untuk meluruskan pemahaman siswa yang kurang tepat. Guru memberi contoh lanjutan dan mengajak siswa menyimpulkan pelajaran hari ini secara bersama-sama. | G8: Guru membagikan lembar refleksi pribadi dan memandu siswa menuliskan jawaban dari pertanyaan “Apa hal paling menarik yang kamu pelajari hari ini dan apa yang masih membingungkan?
A9: 3 | B9: Guru mengkondisikan peserta didik dengan mengecek kehadiran peserta didik melalui lembar absensi dan mengisi jurnal kelas. Kemudian Guru bersama siswa mengingatkan kesepakatan kelas agar lebih kondusif untuk proses belajar mengajar. | C9: Guru membentuk kelompok berisi 4–5 siswa dan membagikan lembar kerja yang memuat tujuan pembelajaran, peran tiap anggota, serta daftar pertanyaan panduan yang harus dijawab melalui pencarian informasi. | D9: Guru mengajak siswa untuk mengamati gambar, benda nyata, atau video, lalu diminta mengemukakan pendapat dan pengalaman mereka yang relevan dengan materi. Guru mencatat ide-ide siswa sebagai dasar untuk melanjutkan ke tahap berikutnya. | E9: Guru menjelaskan materi pembelajaran secara menarik menggunakan alat peraga, cerita, atau media digital agar mudah dipahami siswa. Siswa kemudian diberikan tugas atau aktivitas seperti percobaan sederhana, permainan edukatif, atau kerja kelompok untuk memperdalam pemahaman. Dalam kelompok, siswa mendiskusikan tugas lalu mempresentasikan hasil kerja mereka di depan kelas. Guru membimbing dan memberi umpan balik selama proses berlangsung. | F9: Guru mengulas kembali materi pembelajaran dan memperkuat konsep-konsep penting yang telah dipelajari. Penjelasan tambahan diberikan untuk meluruskan pemahaman siswa yang kurang tepat. Guru memberi contoh lanjutan dan mengajak siswa menyimpulkan pelajaran hari ini secara bersama-sama. | G9: Guru membagikan lembar refleksi pribadi dan memandu siswa menuliskan jawaban dari pertanyaan “Apa hal paling menarik yang kamu pelajari hari ini dan apa yang masih membingungkan?
A10: 4
A11: 5
A12: 6
A13: 7
A14: 8
A15: 9
A16: 10
A17: 11
A18: 12
A19: 13
A20: 14
A21: 15
... A31: 25

Sheet Asesmen 
C1: KEGIATAN ASESMEN
A5: No RPP | B5: Asesmen Awal | C5: Asesmen Formatif | D5: Asesmen Sumatif
A6: 1 | B6: Asesmen yang dilakukan diawal pembelajaran dengan memberikan pertanyaan sederhana terkait materi yang akan dipelajari untuk mengukur pengetahuan awal | C6: Asesmen yang dilakukan selama proses pembelajaran, dapat dilihat berdasarkan keaktifan dalam tugas kelompok ataupun saat berdiskusi menyampaikan pendapat maupun pertanyaan | D6: Asesmen yang dilakukan diakhir kegiatan dapat berupa soal yang berisi pilihan ganda atau essai
A7: 2 | B7: Asesmen yang dilakukan diawal pembelajaran dengan memberikan pertanyaan sederhana terkait materi yang akan dipelajari untuk mengukur pengetahuan awal | C7: Asesmen yang dilakukan selama proses pembelajaran, dapat dilihat berdasarkan keaktifan dalam tugas kelompok ataupun saat berdiskusi menyampaikan pendapat maupun pertanyaan | D7: Asesmen yang dilakukan diakhir kegiatan dapat berupa soal yang berisi pilihan ganda atau essai
A8: 3 | B8: Asesmen yang dilakukan diawal pembelajaran dengan memberikan pertanyaan sederhana terkait materi yang akan dipelajari untuk mengukur pengetahuan awal | C8: Asesmen yang dilakukan selama proses pembelajaran, dapat dilihat berdasarkan keaktifan dalam tugas kelompok ataupun saat berdiskusi menyampaikan pendapat maupun pertanyaan | D8: Asesmen yang dilakukan diakhir kegiatan dapat berupa soal yang berisi pilihan ganda atau essai
A9: 4
A10: 5
A11: 6
A12: 7
A13: 8
A14: 9
A15: 10
A16: 11
A17: 12
A18: 13
A19: 14
A20: 15
... A30: 25

Sheet cetak RPP
A1: RENCANA PELAKSANAAN PEMBELAJARAN | M1: 0
A2: (DEEP LEARNING)
A4: Nama Sekolah | E4: : | F4: ='HALAMAN AWAL'!$D$8 -> SMA JAYA 1 | M4: MENU UTAMA
A5: Mata Pelajaran | E5: : | F5: ='HALAMAN AWAL'!$D$13 -> ILMU PENGETAHUAN ALAM
A6: Kelas / Semester | E6: : | F6: ='HALAMAN AWAL'!$D$14 -> II/ Ganjil (Fase E)
A7: Alokasi Waktu | E7: : | F7: ='HALAMAN AWAL'!$D$17 -> 2x 40 Menit
A9: A. | B9: IDENTIFIKASI
B10: 1. Peserta Didik
C11: ="Kemampuan akademik siswa bervariasi. Sebagian besar siswa menunjukkan penguasaan materi yang cukup baik, namun masih terdapat beberapa siswa yang memerlukan pendampingan tambahan, khususnya dalam memahami "&VLOOKUP(M1,'Desain Pembelajaran'!A7:P31,8,FALSE) -> #N/A
B12: 2. Materi Pelajaran
C13: =VLOOKUP(M1,'Desain Pembelajaran'!A7:H31,8,FALSE) -> #N/A
B14: 3. Dimensi Profil Lulusan
C15: • | D15: =VLOOKUP(M1,'Desain Pembelajaran'!A7:E31,2,FALSE) -> #N/A
C16: • | D16: =VLOOKUP(M1,'Desain Pembelajaran'!A7:E31,3,FALSE) -> #N/A
C17: • | D17: =VLOOKUP(M1,'Desain Pembelajaran'!A7:E31,4,FALSE) -> #N/A
A18: B. | B18: DESAIN PEMBELAJARAN
B19: 1. Tujuan Pembelajaran
C20: • | D20: =VLOOKUP(M1,'Desain Pembelajaran'!A7:E31,5,FALSE) -> #N/A
C21: • | D21: =VLOOKUP(M1,'Desain Pembelajaran'!A7:G31,6,FALSE) -> #N/A
C22: • | D22: =VLOOKUP(M1,'Desain Pembelajaran'!A7:G31,7,FALSE) -> #N/A
B23: 2. Praktik Pedagogik
C24: =VLOOKUP(M1,'Desain Pembelajaran'!A7:I31,9,FALSE) -> #N/A
B25: 3. MITRA PEMBELAJARAN
C26: =VLOOKUP(M1,'Desain Pembelajaran'!A7:J31,10,FALSE) -> #N/A
B27: 4. Pemanfaatan Digital
C28: =VLOOKUP(M1,'Desain Pembelajaran'!A7:K31,11,FALSE) -> #N/A
B29: 5. Lingkungan Pembelajaran
C30: =VLOOKUP(M1,'Desain Pembelajaran'!A7:L31,12,FALSE) -> #N/A
A31: C. | B31: PENGALAMAN BELAJAR
B32: • | C32: Awal (berkesan, bermakna)
C33: 1 | D33: Guru memberikan salam kepada peserta didik untuk mengawali pembelajaran dan dilanjutkan dengan Do'a dipimpin oleh ketua kelas.
C34: 2 | D34: Guru mengkondisikan peserta didik dengan mengecek kehadiran peserta didik melalui lembar absensi dan mengisi jurnal kelas. Kemudian Guru bersama siswa mengingatkan kesepakatan kelas agar lebih kondusif untuk proses belajar mengajar.
C35: 3 | D35: Guru mengajak siswa menyanyikan lagu indonesia raya untuk menguatkan nasionalisme dilanjutkan dengan ice breaking agar siswa lebih siap dan bersemangat mengikuti kegiatan berikutnya.
C36: 4 | D36: ="Guru memberikan pertanyaan pemantik sebagai asesmen awal dengan memberikan pertanyaan sederhana tentang materi yang akan dipelajari untuk mengukur pengetahuan awal, seperti mengapa kita perlu mempelajari tentang "&VLOOKUP(M1,'Desain Pembelajaran'!A7:H31,8,FALSE) -> #N/A
C37: 5 | D37: Guru menyampaikan tujuan pembelajaran secara jelas, disertai penjelasan manfaat yang dapat diperoleh peserta didik setelah mempelajari materi tersebut. Dengan mengetahui tujuan dan manfaatnya, peserta didik diharapkan memahami arah kegiatan yang akan dilakukan dan lebih termotivasi untuk mengikuti pembelajaran secara aktif dan penuh semangat.
B38: • | C38: Inti (berkesadaran, bermakna, menggembirakan)
C39: A. Memahami (Berkesadaran, Bermakna) | G39: Orientasi siswa pada masalah | J39: =VLOOKUP($M$1,'Langkah Pembelajaran'!$A$7:$G$31,2,FALSE) -> #N/A
C40: B. Mengaplikasi (Bermakna, Menggembirakan) | G40: Mengorganisasi siswa untuk belajar | J40: =VLOOKUP($M$1,'Langkah Pembelajaran'!$A$7:$G$31,3,FALSE) -> #N/A
G41: Membimbing penyelidikan | J41: =VLOOKUP($M$1,'Langkah Pembelajaran'!$A$7:$G$31,4,FALSE) -> #N/A
G42: Mengembangkan dan menyajikan hasil | J42: =VLOOKUP($M$1,'Langkah Pembelajaran'!$A$7:$G$31,5,FALSE) -> #N/A
...
